Workbook

Sheet Dash_Lojas
A1: Digite o número
B3: =VLOOKUP($A$7,Info_Loja!$A$2:$L$233,2,FALSE) -> Shopping Piracicaba | E3: =VLOOKUP($A$7,Info_Loja!$A$2:$L$233,11,FALSE) -> SP | H3: IP | I3: =VLOOKUP($A$7,'Detalhes Links Lojas'!$A$2:$AC$216,29,FALSE) -> 129.145.0.0/16 | K3: IP Loopback | L3: =VLOOKUP($A$7,'Detalhes Links Lojas'!$A$2:$AC$216,28,FALSE) -> 10.100.10.69
A6: Loja | B6: Links | H6: Telefonia Fixa | K6: N/S Fortigate | L6: =VLOOKUP($A$7,'Detalhes Links Lojas'!$A$2:$AF$216,32,FALSE) -> FGT40FTK21028599
A7: 580 | B7: Dados | C7: Link 1 | D7: Link 2 | E7: 3° Link Backup | F7: Custo Extra | H7: Linha | I7: =VLOOKUP($A$7,'Telefonia Fixa'!$A$2:$C$234,3,FALSE) -> (19) 3412-1700
B8: Operadora | C8: =VLOOKUP($A$7,'Detalhes Links Lojas'!$A$2:$AA$216,4,FALSE) -> Claro | D8: =VLOOKUP($A$7,'Detalhes Links Lojas'!$A$2:$AA$216,12,FALSE) -> Vivo | E8: =VLOOKUP($A$7,'Detalhes Links Lojas'!$A$2:$AA$216,22,FALSE) -> --- | F8: =VLOOKUP($A$7,'Detalhes Links Lojas'!$A$2:$AA$216,26,FALSE) -> --- | H8: Operadora | I8: =VLOOKUP($A$7,'Telefonia Fixa'!$A$2:$F$234,6,TRUE) -> - | K8: Custo Total | L8: =SUM(C14+I9+D20) -> 534.26
B9: Velocidade | C9: =VLOOKUP($A$7,'Detalhes Links Lojas'!$A$2:$AA$216,9,FALSE) -> 20Mb | D9: =VLOOKUP($A$7,'Detalhes Links Lojas'!$A$2:$AA$216,17,FALSE) -> 600Mb | E9: =VLOOKUP($A$7,'Detalhes Links Lojas'!$A$2:$AA$216,24,FALSE) -> 0 | H9: Valor | I9: =VLOOKUP($A$7,'Telefonia Fixa'!$A$2:$F$234,5,FALSE) -> 0
B10: Tecnologia | C10: =VLOOKUP($A$7,'Detalhes Links Lojas'!$A$2:$AA$216,10,FALSE) -> Dedicado | D10: =VLOOKUP($A$7,'Detalhes Links Lojas'!$A$2:$AA$216,18,FALSE) -> ADSL | E10: =VLOOKUP($A$7,'Detalhes Links Lojas'!$A$2:$AA$216,21,FALSE) -> --- | H10: Telefonia IP
B11: Designação | C11: =VLOOKUP($A$7,'Detalhes Links Lojas'!$A$2:$AA$216,8,FALSE) -> PAA/IP/03834 | D11: =VLOOKUP($A$7,'Detalhes Links Lojas'!$A$2:$AA$216,16,FALSE) -> PAA-817JDDTYE3-013 | E11: =VLOOKUP($A$7,'Detalhes Links Lojas'!$A$2:$AA$216,23,FALSE) -> ---
B12: Vigência | C12: =VLOOKUP($A$7,'Detalhes Links Lojas'!$A$2:$AA$216,7,FALSE) -> 47078 | D12: =VLOOKUP($A$7,'Detalhes Links Lojas'!$A$2:$AA$216,15,FALSE) -> 46674 | H12: Linha | I12: =VLOOKUP($A$7,'Telefonia Ip - Lojas'!$A$2:$H$232,6,FALSE) -> 11 2109-3007
B13: Valor | C13: =VLOOKUP($A$7,'Detalhes Links Lojas'!$A$2:$AA$216,11,FALSE) -> 439.27 | D13: =VLOOKUP($A$7,'Detalhes Links Lojas'!$A$2:$AA$216,19,FALSE) -> 94.99 | E13: =VLOOKUP($A$7,'Detalhes Links Lojas'!$A$2:$AA$216,25,FALSE) -> 0 | F13: =VLOOKUP($A$7,'Detalhes Links Lojas'!$A$2:$AA$216,27,FALSE) -> 0 | H13: Qtd ramais | I13: =VLOOKUP($A$7,'Telefonia Ip - Lojas'!$A$2:$H$232,5,FALSE) -> 1
B14: Total | C14: =SUM(C13+D13+E13+F13) -> 534.26
B17: Telefonia Móvel | F17: Aps | K17: Switches
B18: Número | C18: Operadora | D18: Valor | F18: Tecnologia | G18: Marca/Modelo | H18: Qtde | K18: Modelo | L18: IP | M18: Qtde
B19: =VLOOKUP($A$7,'Telefonia Móvel'!$A$2:$H$236,7,FALSE) -> - | C19: =VLOOKUP($A$7,'Telefonia Móvel'!$A$4:$H$236,2,FALSE) -> - | D19: =VLOOKUP($A$7,'Telefonia Móvel'!$A$2:$H$236,8,FALSE) -> 0 | F19: =VLOOKUP(A7,'[1]Antenas Lojas'!$A$3:$H$235,7,FALSE) -> IAP | G19: =VLOOKUP(A7,'[1]Antenas Lojas'!$A$3:$H$235,8,FALSE) -> Aruba - 205 Aruba - 205 Aruba - 205 Aruba - 205 Aruba - 205 Aruba - 205 | H19: =VLOOKUP(A7,'[1]Antenas Lojas'!$A$3:$H$235,6,FALSE) -> 6 | K19: =VLOOKUP(A7,'[1]Switches Lojas'!$A$3:$D$239,2,FALSE) -> HPE OfficeConnect Switch 1920S HPE OfficeConnect Switch 1920S | L19: =VLOOKUP(A7,'[1]Switches Lojas'!$A$3:$D$239,3,FALSE) -> 129.145.0.8 129.145.0.9 | M19: =VLOOKUP(A7,'[1]Switches Lojas'!$A$3:$D$239,4,FALSE) -> 2
C20: Valor | D20: =VLOOKUP(A7,'Telefonia Móvel'!A2:P236,16,FALSE) -> 0

Sheet Info_Loja
A1: IDLoja | B1: Nome Filial | C1: Telefone Marisa | D1: Tipo | E1: Logradouro | F1: Núm. | G1: Complemento | H1: CEP | I1: Bairro | J1: Cidade | K1: UF | L1: Região Geográfica
A2: 22 | B2: Azenha | C2: (51) 3275-8980 | D2: Rua | E2: Rua da Azenha | F2: 795 | H2: 90160-002 | I2: Azenha | J2: Porto Alegre | K2: RS | L2: Sul
A3: 43 | B3: São Caetano do Sul | C3: (11) 4228-7820 | D3: Rua | E3: R. Manoel Coelho | F3: 316 | G3: 318, 32 E328 | H3: 09510-100 | I3: Centro | J3: São Caetano do Sul | K3: SP | L3: Sudeste
A4: 80 | B4: Campina Grande | C4: (83) 3182-4800 | D4: Rua | E4: R. Maciel Pinheiro | F4: 185 | H4: 58400-100 | I4: Centro | J4: Campina Grande | K4: PB | L4: Nordeste
A5: 87 | B5: Teresina (Centro) | C5: (86) 3302-6104 | D5: Rua | E5: R. Senador Teodoro Pacheco | F5: 1074 | H5: 64001-060 | I5: Centro | J5: Teresina | K5: PI | L5: Nordeste
A6: 120 | B6: São Luiz | C6: (98) 3878-6950 | D6: Rua | E6: R. Grande Oswaldo Cruz | F6: 523 | H6: 65020-250 | I6: Centro | J6: São Luís | K6: MA | L6: Nordeste
A7: 125 | B7: Aracajú | C7: (11) 2109-3045 | D7: Rua | E7: R. João Pessoa | F7: 45 | H7: 49010-130 | I7: Centro | J7: Aracaju | K7: SE | L7: Nordeste
A8: 130 | B8: Florianópolis | C8: (48) 3878-2150 | D8: Rua | E8: Praça XV de Novembro | F8: 111 | H8: 88010-400 | I8: Centro | J8: Florianópolis | K8: SC | L8: Sul
A9: 133 | B9: Shopping Interlagos | C9: (11) 2138-8159 | D9: Shopping | E9: Av. Interlagos | F9: 2255 | H9: 04661-200 | I9: Campo Grande | J9: São Paulo | K9: SP | L9: Sudeste
A10: 135 | B10: Shopping Mueller Joinville | C10: (47) 3803-6550 | D10: Shopping | E10: R. Visconde de Taunay | F10: 234 | H10: 89201-430 | I10: Centro | J10: Joinville | K10: SC | L10: Sul
A11: 136 | B11: Shopping Metrópole | C11: (11) 2138-8534 | D11: Shopping | E11: Pça. Samuel Sabatini | F11: 200 | H11: 09750-902 | I11: Centro | J11: São Bernardo do Campo | K11: SP | L11: Sudeste
A12: 140 | B12: River Shopping | C12: (87) 3201-3984 | D12: Shopping | E12: Av. Mons. Ângelo Sampaio | F12: 100 | G12: lj. 87/88 | H12: 56304-160 | I12: Centro | J12: Petrolina | K12: PE | L12: Nordeste
A13: 142 | B13: Norte Shopping | C13: (21) 2187-7600 | D13: Shopping | E13: Av. Dom Hélder Câmara | F13: 5332 | G13: Salões Comerciais 357/ 358 / 359 / 377/A - Piso S - Norte Shopping | H13: 20771-004 | I13: Cachambi | J13: Rio de Janeiro | K13: RJ | L13: Sudeste
A14: 150 | B14: Pátio Brasil Shopping | C14: (61) 3521-9906 | D14: Shopping | E14: Setor Comercial Sul | F14: Q. 07 | G14: Bloco A, Piso Térreo T3- Loja 1t | H14: 70310-500 | I14: Asa Sul | J14: Brasília | K14: DF | L14: Centro-Oeste
A15: 160 | B15: Riverside Shopping | C15: (86) 3301-2530 | D15: Shopping | E15: Av. Ininga | F15: 1201 | G15: LJ H15/23 E J39/47 | H15: 64046-010 | I15: Jockey Club | J15: Teresina | K15: PI | L15: Nordeste
A16: 165 | B16: Grand Plaza Shopping | C16: (11) 2109-3194 | D16: Shopping | E16: Av. Industrial | F16: 600 | G16: lj. 124 - Bairro Jardim | H16: 09080-500 | I16: Jardim | J16: Santo André | K16: SP | L16: Sudeste
A17: 176 | B17: Internacional Shopping | C17: (11) 2109-6112 | D17: Shopping | E17: Rod. Presidente Dutra KM 397/650 | F17: s/n | G17: Km 397/65 | H17: 07042-050 | I17: Lj B 18 Piso Terreo | J17: Guarulhos | K17: SP | L17: Sudeste
A18: 178 | B18: Buriti Shopping | C18: (62) 3625-7180 | D18: Shopping | E18: Av. Rio Verde | F18: 1 | G18: Qd. 12 / 14 - Loja 153 | H18: 74840-150 | I18: Vila São Tomas | J18: Goiânia | K18: GO | L18: Centro-Oeste
A19: 180 | B19: Litoral Plaza Shopping | C19: (13) 3476-1283 | D19: Shopping | E19: Av. Ayrton Senna | F19: 1511 | G19: Lojas 28, 29, 3 e 31, Xixová | H19: 11726-500 | I19: Sitio do Campo | J19: Praia Grande | K19: SP | L19: Sudeste
A20: 196 | B20: Manaíra Shopping | C20: (83) 3533-4351 | D20: Shopping | E20: R. Manoel Arruda Cavalcante | F20: 805 | G20: Av Gov. Flavio Ribeiro Coutinho - 2º Piso | H20: 58038-680 | I20: Manaira | J20: João Pessoa | K20: PB | L20: Nordeste
A21: 508 | B21: Alameda Shopping | C21: (61) 2102-1314 | D21: Shopping | E21: Estr. Shopping Center Csb | F21: 2 | G21: Lotes 1/2/3/4 - Loja T13, T15 e T15A | H21: 72015-901 | I21: Centro | J21: Brasília | K21: DF | L21: Centro-Oeste
A22: 510 | B22: Shopping Aricanduva | C22: (11) 2109-3178 | D22: Shopping | E22: Av. Aricanduva | F22: 5555 | G22: Âncora 5-Shop. C. Leste | H22: 03527-900 | I22: Jardim Colorado | J22: São Paulo | K22: SP | L22: Sudeste
A23: 512 | B23: Cuiabá | C23: (65) 3928-3249 | D23: Rua | E23: R. Treze de Junho | F23: 265 | H23: 78005-410 | I23: Centro | J23: Cuiabá | K23: MT | L23: Centro-Oeste
A24: 514 | B24: Macapá | C24: (96) 2101-8850 | D24: Rua | E24: R. Cândido Mendes | F24: 1280 | H24: 68900-100 | I24: Centro | J24: Macapá | K24: AP | L24: Norte
A25: 515 | B25: Santo Amaro | C25: (11) 2109-6466 | D25: Rua | E25: Av. Adolfo Pinheiro | F25: 62 | H25: 04734-000 | I25: Santo Amaro | J25: São Paulo | K25: SP | L25: Sudeste
A26: 517 | B26: Rio Branco | C26: (68) 3303-8980 | D26: Rua | E26: Av. Getúlio Vargas | F26: 258 | H26: 69900-060 | I26: Centro | J26: Rio Branco | K26: AC | L26: Norte
A27: 518 | B27: Diadema | C27: (11) 2109-3171 | D27: Rua | E27: Av. Pres. Kennedy | F27: 99 | G27: Av. São José, 26 | H27: 09913-000 | I27: Centro | J27: Diadema | K27: SP | L27: Sudeste
A28: 519 | B28: Porto Velho | C28: (69) 2182-4380 | D28: Rua | E28: Av. Sete de Setembro | F28: 941 | G28: e 941-A | H28: 76801-073 | I28: Centro | J28: Porto Velho | K28: RO | L28: Norte
A29: 520 | B29: Mauá Plaza Shopping | C29: (11) 2109-6054 | D29: Shopping | E29: Av. Antonia Rosa Fioravanti | F29: 3000 | G29: 327 e 338 | H29: 09390-120 | I29: Centro | J29: Mauá | K29: SP | L29: Sudeste
A30: 525 | B30: Sh Rio Mar Aracajú | C30: (79) 3711-2770 | D30: Shopping | E30: R. Delmiro Gouveia | F30: 0 | G30: S/N - Loja Ancora "A" | H30: 49035-900 | I30: Coroa do Meio | J30: Aracaju | K30: SE | L30: Nordeste
A31: 526 | B31: Canoas Shopping | C31: (51) 2102-7280 | D31: Shopping | E31: Av. Guilherme Schell | F31: 6750 | H31: 92310-001 | I31: Centro | J31: Canoas | K31: RS | L31: Sul
A32: 527 | B32: North Shopping Fortaleza | C32: (85) 3392-3684 | D32: Shopping | E32: Av. Bezerra de Menezes | F32: 2450 | G32: lj. 8 1º Piso | H32: 60325-902 | I32: Centro | J32: Fortaleza | K32: CE | L32: Nordeste
A33: 529 | B33: São Leopoldo | C33: (11) 2138-8537 | D33: Rua | E33: R. Independência | F33: 906 | H33: 93010-003 | I33: Centro | J33: São Leopoldo | K33: RS | L33: Sul
A34: 531 | B34: Via Shopping Barreiro | C34: (31) 3211-7350 | D34: Shopping | E34: Av. Afonso Vaz Melo | F34: 640 | G34: Ljs. 235 e 243 | H34: 30640-070 | I34: Barreiro | J34: Belo Horizonte | K34: MG | L34: Sudeste
A35: 534 | B35: Maxi Shopping Jundiaí | C35: (11) 4583-6683 | D35: Shopping | E35: Av. Antonio Frederico Ozanam | F35: 6000 | G35: SUC 14 - 1º PISO | H35: 13215-900 | I35: Vila Rio Branco | J35: Jundiaí | K35: SP | L35: Sudeste
A36: 535 | B36: São José dos Pinhais | C36: (41) 3311-7630 | D36: Rua | E36: R. Quinze de Novembro | F36: 1795 | H36: 83005-000 | I36: Centro | J36: São José dos Pinhais | K36: PR | L36: Sul
A37: 536 | B37: BH Centro | C37: (31) 3242-8500 | D37: Rua | E37: R. Carijós | F37: 645 | H37: 30120-060 | I37: Centro | J37: Belo Horizonte | K37: MG | L37: Sudeste
A38: 543 | B38: Campo Grande | C38: (21) 3622-8730 | D38: Rua | E38: R. Cel. Agostinho | F38: 146 | H38: 23050-360 | I38: Campo Grande | J38: Rio de Janeiro | K38: RJ | L38: Sudeste | M38: encerrada
A39: 544 | B39: Shopping Penha | C39: (11) 2109-6021 | D39: Shopping | E39: R. Dr. João Ribeiro | F39: 304 | G39: SUC 1711/1712 | H39: 03634-900 | I39: Penha de Franca | J39: São Paulo | K39: SP | L39: Sudeste
A40: 546 | B40: São Bernardo | C40: (11) 2109-3172 | D40: Rua | E40: R. Mal. Deodoro | F40: 900 | H40: 09710-001 | I40: Centro | J40: São Bernardo do Campo | K40: SP | L40: Sudeste
...

Sheet Telefonia Fixa
A1: Loja | B1: Nome Filial | C1: Telefone Marisa | D1: Telefone Fixo | E1: Valor Cobrado | F1: Operadora
A2: 22 | B2: Azenha | C2: (51) 3275-8980 | D2: - | F2: -
A3: 43 | B3: São Caetano do Sul | C3: (11) 4228-7820 | D3: - | F3: -
A4: 80 | B4: Campina Grande | C4: (83) 3182-4800 | D4: - | F4: -
A5: 87 | B5: Teresina (Centro) | C5: (86) 3302-6104 | D5: - | F5: -
A6: 120 | B6: São Luiz | C6: (98) 3878-6950 | D6: - | F6: -
A7: 125 | B7: Aracajú | C7: (11) 2109-3045 | D7: - | F7: -
A8: 130 | B8: Florianópolis | C8: (48) 3878-2150 | D8: - | F8: -
A9: 133 | B9: Shopping Interlagos | C9: (11) 2138-8159 | D9: - | F9: -
A10: 135 | B10: Shopping Mueller Joinville | C10: (47) 3803-6550 | D10: - | F10: -
A11: 136 | B11: Shopping Metrópole | C11: (11) 2138-8534 | D11: - | F11: -
A12: 140 | B12: River Shopping | C12: (87) 3201-3984 | D12: - | F12: -
A13: 142 | B13: Norte Shopping | C13: (21) 2187-7600 | D13: - | F13: -
... A18: 178 | B18: Buriti Shopping | C18: (62) 3625-7180 | D18: - | F18: -
A19: 180 | B19: Litoral Plaza Shopping | C19: (13) 3476-1283 | D19: (13)3476-1288 | E19: 23.475709 | F19: TELEFONICA
A20: 196 | B20: Manaíra Shopping | C20: (83) 3533-4351 | D20: - | F20: -
A21: 508 | B21: Alameda Shopping | C21: (61) 2102-1314 | D21: - | F21: -
A22: 510 | B22: Shopping Aricanduva | C22: (11) 2109-3178 | D22: - | F22: -
A23: 512 | B23: Cuiabá | C23: (65) 3928-3249 | D23: - | F23: -
A24: 514 | B24: Macapá | C24: (96) 2101-8850 | D24: - | F24: -
A25: 515 | B25: Santo Amaro | C25: (11) 2109-6466 | D25: - | F25: -
A26: 517 | B26: Rio Branco | C26: (68) 3303-8980 | D26: - | F26: -
A27: 518 | B27: Diadema | C27: (11) 2109-3171 | D27: - | F27: -
A28: 519 | B28: Porto Velho | C28: (69) 2182-4380 | D28: - | F28: -
A29: 520 | B29: Mauá Plaza Shopping | C29: (11) 2109-6054 | D29: - | F29: -
A30: 525 | B30: Sh Rio Mar Aracajú | C30: (79) 3711-2770 | D30: - | F30: -
A31: 526 | B31: Canoas Shopping | C31: (51) 2102-7280 | D31: - | F31: -
A32: 527 | B32: North Shopping Fortaleza | C32: (85) 3392-3684 | D32: (85)3392-3680 | E32: 28.76 | F32: EMBRATEL
A33: 529 | B33: São Leopoldo | C33: (11) 2138-8537 | D33: - | F33: -
A34: 531 | B34: Via Shopping Barreiro | C34: (31) 3211-7350 | D34: - | F34: -
A35: 534 | B35: Maxi Shopping Jundiaí | C35: (11) 4583-6683 | D35: - | F35: -
A36: 535 | B36: São José dos Pinhais | C36: (41) 3311-7630 | D36: - | F36: -
A37: 536 | B37: BH Centro | C37: (31) 3242-8500 | D37: - | F37: -
A38: 543 | B38: Campo Grande | C38: (21) 3622-8730 | D38: - | F38: -
A39: 544 | B39: Shopping Penha | C39: (11) 2109-6021 | D39: - | F39: -
A40: 546 | B40: São Bernardo | C40: (11) 2109-3172 | D40: - | F40: -
A41: 547 | B41: Gonzaga | C41: (13) 3208-6481 | D41: 1332086499 | E41: 86.55 | F41: EMBRATEL
A42: 548 | B42: Curitiba | C42: (11) 2138-8530 | D42: - | F42: -
A43: 549 | B43: Novo Shopping Center Ribeirão Preto | C43: (16) 3965-8510 | D43: - | F43: -
A44: 550 | B44: Guarulhos | C44: (11) 2109-6017 | D44: - | F44: -
...

Sheet Telefonia Ip - Lojas
A1: Loja | B1: Filial | C1: Estado | D1: Hunt Group | E1: Qtde aps ativos | F1: Req/Num loja | G1: Data Instalação | H1: Ramais Criados | I1: OBS
A2: 22 | B2: Azenha | C2: RS | D2: 111 | E2: 1 | F2: 11 2109-3151 | G2: 45327 | H2: 60221
A3: 43 | B3: São Caetano do Sul | C3: SP | D3: 112 | E3: 1 | F3: 11 2109-3152 | G3: 45327 | H3: 60431
A4: 80 | B4: Campina Grande | C4: PB | D4: 113 | E4: 1 | F4: 11 2109-3153 | G4: 45394 | H4: 60801
A5: 87 | B5: Teresina (Centro) | C5: pi | D5: 114 | E5: 1 | F5: 11 2109-3154 | G5: 45359 | H5: 60871
A6: 120 | B6: São Luiz | C6: MA | D6: 115 | E6: 1 | F6: 11 2109-3155 | G6: 45327 | H6: 61201
A7: 125 | B7: Aracajú | C7: SE | D7: 22 | E7: 4 | F7: 11 2109-3045 | G7: 45084 | H7: 61251 a 61254
A8: 130 | B8: Florianópolis | C8: sc | D8: 116 | E8: 1 | F8: 11 2109-3156 | G8: 45489 | H8: 61301
A9: 133 | B9: Shop. Interlagos | C9: SP | D9: 72 | E9: 3 | F9: 11 2138-8159 | G9: 45043 | H9: 61331 a 61334
A10: 135 | B10: Shop. Mueller Joinville | C10: sc | D10: 117 | E10: 1 | F10: 11 2109-3157 | G10: 45363 | H10: 61351
A11: 136 | B11: Shop. Metrópole | C11: SP | D11: 94 | E11: 4 | F11: 11 2138-8534 | G11: 45056 | H11: 61361 a 61364
A12: 140 | B12: River Shopping | C12: pe | D12: 118 | E12: 1 | F12: 11 2109-3158 | G12: 45362 | H12: 61401
A13: 142 | B13: Norte Shopping | C13: RJ | D13: 119 | E13: 1 | F13: 11 2109-3159 | G13: 45328 | H13: 61421
A14: 150 | B14: Pátio Brasil Shop. | C14: DF | D14: 121 | E14: 1 | F14: 11 2109-3161 | G14: 45328 | H14: 61501 | I14: DDR desativado em 06/06/2025
A15: 160 | B15: Riverside Walk Shop. | C15: PI | D15: 122 | E15: 1 | F15: 11 2109-3162 | G15: 45328 | H15: 61601
A16: 165 | B16: Grand Plaza Shop. | C16: SP | D16: 73 | E16: 3 | F16: 11 2109-3194 | G16: 45043 | H16: 61651 a 61654
A17: 176 | B17: Internacional Shop. Guarulhos | C17: SP | D17: 23 | E17: 4 | F17: 11 2109-6112 | G17: 45043 | H17: 61761 a 61764
A18: 178 | B18: Buriti Shop. | C18: GO | D18: 124 | E18: 1 | F18: 11 2109-3164 | G18: 45328 | H18: 61781
A19: 180 | B19: Litoral Plaza Shop. | C19: SP | D19: 125 | E19: 1 | F19: 11 2109-3165 | G19: 45362 | H19: 61801
A20: 196 | B20: Manaíra Shop. | C20: PB | D20: 41 | E20: 3 | F20: 11 2138-8564 | G20: 45254 | H20: 61961 a 61963
A21: 508 | B21: Alameda Shop. | C21: DF | D21: 126 | E21: 1 | F21: 11 2109-3166 | G21: 45489 | H21: 65081
A22: 510 | B22: Shop. Aricanduva | C22: SP | D22: 63 | E22: 5 | F22: 11 2109-3178 | G22: 45057 | H22: 65101 a 65105
A23: 512 | B23: Cuiabá | C23: MT | D23: 127 | E23: 1 | F23: 11 2109-3167 | G23: 45488 | H23: 65121
A24: 514 | B24: Macapá | C24: AP | D24: 128 | E24: 1 | F24: 11 2109-3168 | G24: 45329 | H24: 65141 | I24: DDR desativado em 02/06/2025
A25: 515 | B25: Santo Amaro | C25: SP | D25: 55 | E25: 4 | F25: 11 2109-6466 | G25: 45043 | H25: 65151 a 65154
A26: 517 | B26: Rio Branco | C26: ac | D26: 129 | E26: 1 | F26: 11 2109-3169 | G26: 45365 | H26: 65171
A27: 518 | B27: Diadema | C27: SP | D27: 69 | E27: 6 | F27: 11 2109-3171 | G27: 45058 | H27: 65181 a 65186
A28: 519 | B28: Porto Velho | C28: ro | D28: 130 | E28: 1 | F28: 11 2109-3175 | G28: 45817 | H28: 65191 a 65192
A29: 520 | B29: Mauá Plaza Shop. | C29: SP | D29: 40 | E29: 4 | F29: 11 2109-6054 | G29: 45125 | H29: 65201 a 65204
A30: 525 | B30: RioMar Aracajú | C30: se | D30: 131 | E30: 1 | F30: 11 2109-3180 | G30: 45337 | H30: 65251
A31: 526 | B31: Canoas Shop. | C31: rs | D31: 132 | E31: 1 | F31: 11 2109-3182 | G31: 45362 | H31: 65261
A32: 527 | B32: North Shop. Fortaleza | C32: ce | D32: 133 | E32: 1 | F32: 11 2109-3183 | G32: 45364 | H32: 65271
A33: 529 | B33: São Leopoldo | C33: RS | D33: 38 | E33: 4 | F33: 11 2138-8537 | G33: 45170 | H33: 65291 a 65294
A34: 531 | B34: Via Shop. | C34: MG | D34: 134 | E34: 1 | F34: 11 2109-3184 | G34: 45364 | H34: 65311
A35: 534 | B35: Maxi Shop. Jundiaí | C35: SP | D35: 135 | E35: 3 | F35: 11 2109-3185 | G35: 45819 | H35: 65341 a 65343
A36: 535 | B36: São José dos Pinhais | C36: PR | D36: 136 | E36: 1 | F36: 11 2109-3186 | G36: 45359 | H36: 65351
A37: 536 | B37: BH Centro | C37: MG | D37: 137 | E37: 1 | F37: 11 2109-3187 | G37: 45391 | H37: 65361
A38: 544 | B38: Shop. Penha | C38: SP | D38: 39 | E38: 4 | F38: 11 2109-6021 | G38: 45043 | H38: 65441 a 65444
A39: 546 | B39: São Bernardo do Campo | C39: SP | D39: 68 | E39: 4 | F39: 11 2109-3172 | G39: 45061 | H39: 65461 a 65466
A40: 547 | B40: Gonzaga | C40: SP | D40: 139 | E40: 1 | F40: 11 2109-3189 | G40: 45329 | H40: 65471
...

Sheet EC-Tivit-CDs
A1: Site | B1: CR | C1: Operadora 1 | D1: Tipo | E1: Velocidade | F1: Data de Ativação | G1: Vigencia | H1: Valor | I1: Designação | J1: Operadora 2 | K1: Tipo | L1: Velocidade | M1: Data de Ativação | N1: Vigencia | O1: Valor | P1: Designação | Q1: Operadora 3 | R1: Tipo | S1: Velocidade | T1: Data de Ativação | U1: Vigencia | V1: Valor | W1: Designação | X1: Operadora 4 | Y1: Tipo | Z1: Velocidade | AA1: Data de Ativação | AB1: Vigencia | AC1: Valor | AD1: Designação | AE1: Operadora 5 | AF1: Tipo | AG1: Velocidade | AH1: Data de Ativação | AI1: Vigencia | AJ1: Valor | AK1: Designação | AL1: Operadora 6 | AM1: Tipo | AN1: Velocidade | AO1: Data de Ativação | AP1: Vigencia | AQ1: Valor | AR1: Designação | AT1: IP Loopback | AU1: IP Local
A2: EC | B2: 41100 | C2: Embratel | D2: Dedicado | E2: 500Mb | F2: 44903 | G2: 45999 | H2: 3181.21 | I2: SPO/IP/40295 | J2: Vivo | K2: Dedicado | L2: 1 GB | M2: 45595 | N2: 46690 | O2: 3434.64 | P2: 110003392209490 | Q2: Algar | R2: L2L (EC-Tivit) | S2: 1 GB | T2: 44750 | U2: 45846 | V2: 2345.89 | W2: 8880105
A3: Tivit | C3: Embratel | D3: Dedicado | E3: 1Gb | F3: 44901 | G3: 45997 | H3: 5657.1 | I3: SPO/IP/70714 | J3: Vivo | K3: Dedicado | L3: 1 GB | M3: 45132 | N3: 46228 | O3: 3763.7 | P3: 830000171641295 | Q3: Algar | R3: L2L (Tivit-EC) | S3: 1 GB | T3: 44750 | U3: 45846 | V3: 2345.89 | W3: 8880104 | X3: EBT (Sitef) | Y3: MPLS | Z3: 20MB | AC3: 4993.06 | AD3: SPO/IP/55340 | AE3: Algar | AF3: L2L(Tivit-CD) | AG3: 50 MB | AH3: 44651 | AI3: Vencido | AJ3: 1034.56 | AK3: 8788650 | AL3: Vivo (Sitef) | AM3: MPLS | AN3: 4Mb | AO3: 45070 | AP3: Vencido | AQ3: 3998.82 | AR3: 110005641094794
A4: CD Itaqua | B4: CD820 | C4: Vivo | D4: Dedicado | E4: 200Mb | F4: 45338 | G4: 46434 | H4: 1760.03 | I4: 113004643101796 | J4: WCS | K4: Dedicado | L4: 100 MB | M4: 45609 | N4: 46704 | O4: 430 | P4: CD 820 - Itaquaquecetuba - SP | Q4: Algar | R4: L2L (CD-Tivit) | S4: 50 MB | T4: 44651 | U4: Vencido | V4: 1034.56 | W4: 8788652 | AU4: 10.8.120.0/22
A5: CD Blumenau | B5: CD811 | C5: Algar | D5: Dedicado | E5: 20 MB | F5: 44596 | G5: Vencido | H5: 980.92 | I5: 8756818/8756819 | J5: Embratel | K5: Dedicado | L5: 20 MB | M5: 44714 | N5: Vencido | O5: 484.62 | P5: BNU/IP/01514 | AU5: 10.8.100.0/22
A6: CD Goiânia | B6: CD807 | C6: Algar | D6: Dedicado | E6: 10MB | F6: 44617 | G6: Vencido | H6: 450.13 | I6: 8754445/8754447 | J6: Vivo | K6: Dedicado | L6: 10 MB | M6: 44470 | N6: Vencido | O6: 584.64 | P6: 621980152126996 | AU6: 10.8.108.0/22
A7: CD Navegantes | B7: CD818 | C7: Algar | D7: Dedicado | E7: 20 MB | F7: 44589 | G7: Vencido | H7: 566.52 | I7: 8754444/8754446 | J7: Mega | K7: Dedicado | L7: 20 MB | M7: 44735 | N7: Vencido | O7: 897.79 | P7: TIT000872 | AU7: 10.8.107.0/22
B8: SITEF | C8: Vivo-P2 EQN-ALA | D8: MPLS | E8: 2MB | F8: 43738 | G8: Vencido | H8: 832.3 | I8: 110714191224793 | J8: Embratel | K8: MPLS | L8: 2Mb | O8: 1343.81 | P8: BRE/IP/25280
C9: Vivo-P1 EQN-MIG | D9: MPLS | E9: 2MB | F9: 43738 | G9: Vencido | H9: 832.3 | I9: 110003106383097 | J9: Embratel | K9: MPLS | L9: 2Mb | O9: 1909.68 | P9: SPO/IP/55325
B15: EC | C15: =SUM(H2+O2+V2) -> 8961.74
B16: TIVIT | C16: =SUM(H3+O3+V3+AJ3) -> 12801.25
B17: CD Itaqua | C17: =SUM(H4+O4+V4) -> 3224.59
B18: CD Blumenau | C18: =SUM(H5+O5+V5) -> 1465.54
B19: CD Goiânia | C19: =SUM(H6+O6+V6) -> 1034.77
B20: CD Navegantes | C20: =SUM(H7+O7+V7) -> 1464.31
B21: SITEF | C21: =SUM(AC3+AQ3+H8+H9+O8+O9) -> 13909.97
B22: Custo Total | C22: =SUM(C15:C21) -> 42862.17

Sheet Telefonia Móvel
A1: CR | B1: Operadora | C1: Plano | D1: Conta | E1: Localidade | F1: Telefonia | G1: Numero | H1: Valor | P1: Total
A2: 22 | B2: - | C2: - | D2: - | F2: MÓVEL | G2: - | H2: 0 | P2: =SUM(I2:O2) -> 0
A3: 43 | B3: - | C3: - | D3: - | F3: MÓVEL | G3: - | H3: 0 | P3: =SUM(I3:O3) -> 0
A4: 80 | B4: VIVO | C4: PLANO INTERNET BOX PJ | D4: 2027121479 | E4: 080 - CAMPINA GRANDE | F4: MÓVEL | G4: 11995086262 | H4: 104.05 | I4: 104.05 | P4: =SUM(I4:O4) -> 104.05
A5: 87 | B5: VIVO | C5: SMART EMPRESAS 2GB D | D5: 381199225 | E5: 087 - TERESINA | F5: MÓVEL | G5: 11971053948 11950616361 11995061269 | H5: R$ 18,99 R$ 18,99 R$ 18,99 | I5: 18.99 | J5: 18.99 | K5: 18.99 | P5: =SUM(I5:O5) -> 56.97
A6: 120 | B6: VIVO | C6: SMART EMPRESAS 0.5GB D | D6: 381199225 | E6: 120 - SÃO LUIZ | F6: MÓVEL | G6: 11944706003 11944439242 | H6: R$ 30,50 R$ 18,99 | I6: 30.5 | J6: 18.99 | P6: =SUM(I6:O6) -> 49.49
A7: 140 | B7: VIVO | C7: SMART EMPRESAS 2GB D | D7: 381199225 | E7: 140 - RIVER SHOP | F7: MÓVEL | G7: 16996333608 19996458099 21995002687 79998442585 | H7: R$ 18,99 R$ 18,99 R$ 18,99 R$ 30,50 | I7: 18.99 | J7: 18.99 | K7: 18.99 | L7: 30.5 | P7: =SUM(I7:O7) -> 87.47
A8: 142 | B8: CLARO | C8: PLANO TOTAL SHARE 2.0 | D8: 832140239 | E8: 142 - NORTE SHOP | F8: MÓVEL | G8: 11992175076 11992350946 11992979384 11993155324 | H8: R$ 62,23 R$ 50,59 R$ 50,59 R$ 50,59 | I8: 62.23 | J8: 50.59 | K8: 50.59 | L8: 50.59 | P8: =SUM(I8:O8) -> 214
A9: 125 | B9: - | C9: - | D9: - | F9: MÓVEL | G9: - | H9: 0 | P9: =SUM(I9:O9) -> 0
A10: 130 | B10: - | C10: - | D10: - | F10: MÓVEL | G10: - | H10: 0 | P10: =SUM(I10:O10) -> 0
A11: 133 | B11: - | C11: - | D11: - | F11: MÓVEL | G11: - | H11: 0 | P11: =SUM(I11:O11) -> 0
A12: 135 | B12: - | C12: - | D12: - | F12: MÓVEL | G12: - | H12: 0 | P12: =SUM(I12:O12) -> 0
A13: 136 | B13: - | C13: - | D13: - | F13: MÓVEL | G13: - | H13: 0 | P13: =SUM(I13:O13) -> 0
A14: 150 | B14: VIVO | C14: SMART EMPRESAS 2GB D | D14: 381199225 | E14: 150 - PATIO BRASIL SHOP | F14: MÓVEL | G14: 51980635226 21967265582 | H14: R$ 18,99 R$ 18,99 | I14: 18.99 | J14: 18.99 | P14: =SUM(I14:O14) -> 37.98
A15: 160 | B15: VIVO | C15: SMART EMPRESAS 2GB D | D15: 381199225 | E15: 160 - RIVERSIDE WALK SHOP | F15: MÓVEL | G15: 11944594725 11944705147 | H15: R$ 18,99 R$ 18,99 | I15: 18.99 | J15: 18.99 | P15: =SUM(I15:O15) -> 37.98
A16: 178 | B16: VIVO | C16: SMART EMPRESAS 2GB D | D16: 381199225 | E16: 178 - BURUTI SHOP | F16: MÓVEL | G16: 11943930362 11996831429 | H16: R$ 18,99 R$ 18,99 | I16: 18.99 | J16: 18.99 | P16: =SUM(I16:O16) -> 37.98
A17: 508 | B17: VIVO | C17: SMART EMPRESAS 2GB D | D17: 381199225 | E17: 508 - ALAMEDA SHOP | F17: MÓVEL | G17: 11971405188 11996287684 | H17: R$ 18,99 R$ 18,99 | I17: 18.99 | J17: 18.99 | P17: =SUM(I17:O17) -> 37.98
A18: 165 | B18: - | C18: - | D18: - | E18: 165 - | F18: MÓVEL | G18: - | H18: 0 | P18: =SUM(I18:O18) -> 0
A19: 176 | B19: - | C19: - | D19: - | E19: 176 - SHOP ITERNACIONAL | F19: MÓVEL | G19: - | H19: 0 | P19: =SUM(I19:O19) -> 0
A20: 512 | B20: VIVO | C20: SMART EMPRESAS 2GB D | D20: 381199225 | E20: 512 - CUIABÁ | F20: MÓVEL | G20: 65996326335 | H20: 18.99 | I20: 18.99 | P20: =SUM(I20:O20) -> 18.99
A21: 180 | B21: - | C21: - | D21: - | F21: MÓVEL | G21: - | H21: 0 | P21: =SUM(I21:O21) -> 0
A22: 196 | B22: - | C22: - | D22: - | F22: MÓVEL | G22: - | H22: 0 | P22: =SUM(I22:O22) -> 0
A23: 514 | B23: VIVO | C23: SMART EMPRESAS 2GB D | D23: 381199225 | E23: 514 - MACAPÁ | F23: MÓVEL | G23: 11930280682 11999131734 | H23: R$ 18,99 R$ 31,99 | I23: 18.99 | J23: 31.99 | P23: =SUM(I23:O23) -> 50.98
A24: 510 | B24: - | C24: - | D24: - | E24: 510 - SHOP ARICANDUVA | F24: MÓVEL | G24: - | H24: 0 | P24: =SUM(I24:O24) -> 0
A25: 517 | B25: VIVO | C25: SMART EMPRESAS 2GB D | D25: 381199225 | E25: 517 - RIO BRANCO | F25: MÓVEL | G25: 19999319448 31996463551 51980476592 51996463769 | H25: R$ 18,99 R$ 18,99 R$ 18,99 R$ 18,99 | I25: 18.99 | J25: 18.99 | K25: 18.99 | L25: 18.99 | P25: =SUM(I25:O25) -> 75.96
A26: 519 | B26: CLARO | C26: PLANO TOTAL SHARE 2.0 | D26: 167840395 | E26: 519 - PORTO VELHO | F26: MÓVEL | G26: 69992372309 69993189066 69993261979 69993409924 | H26: R$ 40,47 R$ 40,47 R$ 40,47 R$ 40,47 | I26: 40.47 | J26: 40.47 | K26: 40.47 | L26: 40.47 | P26: =SUM(I26:O26) -> 161.88
A27: 515 | B27: - | C27: - | D27: - | E27: 515 - SANTO AMARO | F27: MÓVEL | G27: - | H27: 0 | P27: =SUM(I27:O27) -> 0
A28: 529 | B28: CLARO | C28: PLANO TOTAL SHARE 2.0 | D28: 167858424 | E28: 529 - SÃO LEOPONDO | F28: MÓVEL | G28: 51991708568 51991711470 51991722682 11988237933 | H28: R$ 32,19 R$ 32,19 R$ 32,19 R$ 157,79 | I28: 32.19 | J28: 32.19 | K28: 32.19 | L28: 157.79 | P28: =SUM(I28:O28) -> 254.36
A29: 518 | B29: - | C29: - | D29: - | F29: MÓVEL | G29: - | H29: 0 | P29: =SUM(I29:O29) -> 0
A30: 531 | B30: CLARO | C30: PLANO TOTAL SHARE 2.0 | D30: 105638675 | E30: 531 - VIA SHOP | F30: MÓVEL | G30: 31992430060 | H30: 52.28 | I30: 52.28 | P30: =SUM(I30:O30) -> 52.28
A31: 520 | B31: - | C31: - | D31: - | F31: MÓVEL | G31: - | H31: 0 | P31: =SUM(I31:O31) -> 0
A32: 525 | B32: - | C32: - | D32: - | F32: MÓVEL | G32: - | H32: 0 | P32: =SUM(I32:O32) -> 0
A33: 526 | B33: - | C33: - | D33: - | F33: MÓVEL | G33: - | H33: 0 | P33: =SUM(I33:O33) -> 0
A34: 527 | B34: - | C34: - | D34: - | F34: MÓVEL | G34: - | H34: 0 | P34: =SUM(I34:O34) -> 0
A35: 536 | B35: CLARO CLARO CLARO VIVO | C35: PLANO TOTAL SHARE 2.0 PLANO TOTAL SHARE 2.0 PLANO TOTAL SHARE 2.0 SMART EMPRESAS 2GB D | D35: 832140239 832140239 832140239 381199225 | E35: 536 - BH CENTRO | F35: MÓVEL | G35: 11961798677 11991366958 11993141259 31998576863 | H35: R$ 50,59 R$ 50,59 R$ 50,59 R$ 18,99 | I35: 50.59 | J35: 50.59 | K35: 50.59 | L35: 18.99 | P35: =SUM(I35:O35) -> 170.76
A36: 543 | B36: VIVO | C36: SMART EMPRESAS 2GB D | D36: 381199225 | E36: 543 - CAMPO GRANDE | F36: MÓVEL | G36: 21967265450 | H36: 18.99 | I36: 18.99 | P36: =SUM(I36:O36) -> 18.99
A37: 534 | B37: - | C37: - | D37: - | F37: MÓVEL | G37: - | H37: 0 | P37: =SUM(I37:O37) -> 0
A38: 535 | B38: - | C38: - | D38: - | F38: MÓVEL | G38: - | H38: 0 | P38: =SUM(I38:O38) -> 0
A39: 544 | B39: CLARO | C39: PLANO TOTAL SHARE 2.0 | D39: 832140239 | E39: 544 - SHOP PENHA | F39: MÓVEL | G39: 11913072083 | H39: 49.48 | I39: 49.48 | P39: =SUM(I39:O39) -> 49.48
A40: 546 | B40: VIVO | C40: SMART EMPRESAS 2GB D | D40: 381199225 | E40: 546 - SBC | F40: MÓVEL | G40: 11963974721 | H40: 18.99 | I40: 18.99 | P40: =SUM(I40:O40) -> 18.99
...

Sheet Dash_Custo
A2: Custo por Operadora - Lojas | F2: Custo por Operadora - EC-CDs-Datacenter
A3: Operadora | B3: Qtde de Links | C3: Valor Total | D3: Média | F3: Operadora | G3: Qtde de Links | H3: Valor Total | I3: Média
A4: Embratel | B4: =COUNTIF('Detalhes Links Lojas'!D$2:D$216,"Embratel") + COUNTIF('Detalhes Links Lojas'!L$2:L$216,"Embratel") -> 4 | C4: =SUMIF('Detalhes Links Lojas'!D$2:D$216,"Embratel",'Detalhes Links Lojas'!K$2:K$216) + SUMIF('Detalhes Links Lojas'!L$2:L$216,"Embratel",'Detalhes Links Lojas'!S$2:S$216) -> 1862.71 | D4: =IFERROR(C4/B4,0) -> 465.6775 | F4: Claro | G4: =COUNTIF('Detalhes EC-EQX-CDs'!D$2:D$7,"Claro") + COUNTIF('Detalhes EC-EQX-CDs'!K$2:K$7,"Claro") + COUNTIF('Detalhes EC-EQX-CDs'!Z$2:Z$7,"Claro") -> 2 | H4: =SUMIF('Detalhes EC-EQX-CDs'!D$2:D$7,"Claro",'Detalhes EC-EQX-CDs'!J$2:J$7) + SUMIF('Detalhes EC-EQX-CDs'!K$2:K$7,"Claro",'Detalhes EC-EQX-CDs'!Q$2:Q$7) + SUMIF('Detalhes EC-EQX-CDs'!Z$2:Z$7,"Claro",'Detalhes EC-EQX-CDs'!AF$2:AF$7) -> 3876.3 | I4: =IFERROR(H4/G4,0) -> 1938.15
A5: Claro | B5: =COUNTIF('Detalhes Links Lojas'!D$2:D$216,"Claro") + COUNTIF('Detalhes Links Lojas'!L$2:L$216,"Claro") -> 175 | C5: =SUMIF('Detalhes Links Lojas'!D2:D216,"Claro",'Detalhes Links Lojas'!K2:K216) + SUMIF('Detalhes Links Lojas'!L2:L216,"Claro",'Detalhes Links Lojas'!S2:S216) -> 71848.24 | D5: =IFERROR(C5/B5,0) -> 410.56137 | F5: Vivo | G5: =COUNTIF('Detalhes EC-EQX-CDs'!D$2:D$7,"Vivo") + COUNTIF('Detalhes EC-EQX-CDs'!K$2:K$7,"Vivo") + COUNTIF('Detalhes EC-EQX-CDs'!Z$2:Z$7,"Vivo") -> 4 | H5: =SUMIF('Detalhes EC-EQX-CDs'!D$2:D$7,"Vivo",'Detalhes EC-EQX-CDs'!J$2:J$7) + SUMIF('Detalhes EC-EQX-CDs'!K$2:K$7,"Vivo",'Detalhes EC-EQX-CDs'!Q$2:Q$7) + SUMIF('Detalhes EC-EQX-CDs'!Z$2:Z$7,"Vivo",'Detalhes EC-EQX-CDs'!AF$2:AF$7) -> 9800.19 | I5: =IFERROR(H5/G5,0) -> 2450.0475
A6: Vivo | B6: =COUNTIF('Detalhes Links Lojas'!D$2:D$216,"Vivo") + COUNTIF('Detalhes Links Lojas'!L$2:L$216,"Vivo") -> 76 | C6: =SUMIF('Detalhes Links Lojas'!D2:D216,"Vivo",'Detalhes Links Lojas'!K2:K216) + SUMIF('Detalhes Links Lojas'!L2:L216,"Vivo",'Detalhes Links Lojas'!S2:S216) -> 22187.44 | D6: =IFERROR(C6/B6,0) -> 291.94 | F6: Fibrion | G6: =COUNTIF('Detalhes EC-EQX-CDs'!D$2:D$7,"Fibrion") + COUNTIF('Detalhes EC-EQX-CDs'!K$2:K$7,"Fibrion") + COUNTIF('Detalhes EC-EQX-CDs'!Z$2:Z$7,"Fibrion") -> 1 | H6: =SUMIF('Detalhes EC-EQX-CDs'!D$2:D$7,"Fibrion",'Detalhes EC-EQX-CDs'!J$2:J$7) + SUMIF('Detalhes EC-EQX-CDs'!K$2:K$7,"Fibrion",'Detalhes EC-EQX-CDs'!Q$2:Q$7) + SUMIF('Detalhes EC-EQX-CDs'!Z$2:Z$7,"Fibrion",'Detalhes EC-EQX-CDs'!AF$2:AF$7) -> 430 | I6: =IFERROR(H6/G6,0) -> 430
A7: Fibrion | B7: =COUNTIF('Detalhes Links Lojas'!D$2:D$216,"Fibrion") + COUNTIF('Detalhes Links Lojas'!L$2:L$216,"Fibrion") -> 28 | C7: =SUMIF('Detalhes Links Lojas'!D2:D216,"Fibrion",'Detalhes Links Lojas'!K2:K216) + SUMIF('Detalhes Links Lojas'!L2:L216,"Fibrion",'Detalhes Links Lojas'!S2:S216) -> 14240.72 | D7: =IFERROR(C7/B7,0) -> 508.59714 | F7: Mundivox | G7: =COUNTIF('Detalhes EC-EQX-CDs'!D$2:D$7,"Mundivox") + COUNTIF('Detalhes EC-EQX-CDs'!K$2:K$7,"Mundivox") + COUNTIF('Detalhes EC-EQX-CDs'!Z$2:Z$7,"Mundivox") -> 1 | H7: =SUMIF('Detalhes EC-EQX-CDs'!D$2:D$7,"Mundivox",'Detalhes EC-EQX-CDs'!J$2:J$7) + SUMIF('Detalhes EC-EQX-CDs'!K$2:K$7,"Mundivox",'Detalhes EC-EQX-CDs'!Q$2:Q$7) + SUMIF('Detalhes EC-EQX-CDs'!Z$2:Z$7,"Mundivox",'Detalhes EC-EQX-CDs'!AF$2:AF$7) -> 2750 | I7: =IFERROR(H7/G7,0) -> 2750
A8: Vero | B8: =COUNTIF('Detalhes Links Lojas'!D$2:D$216,"Vero") + COUNTIF('Detalhes Links Lojas'!L$2:L$216,"Vero") -> 66 | C8: =SUMIF('Detalhes Links Lojas'!D2:D216,"Vero",'Detalhes Links Lojas'!K2:K216) + SUMIF('Detalhes Links Lojas'!L2:L216,"Vero",'Detalhes Links Lojas'!S2:S216) -> 19667.81 | D8: =IFERROR(C8/B8,0) -> 297.99712 | F8: Algar | G8: =COUNTIF('Detalhes EC-EQX-CDs'!D$2:D$7,"Algar") + COUNTIF('Detalhes EC-EQX-CDs'!K$2:K$7,"Algar") + COUNTIF('Detalhes EC-EQX-CDs'!Z$2:Z$7,"Algar") -> 3 | H8: =SUMIF('Detalhes EC-EQX-CDs'!D$2:D$7,"Algar",'Detalhes EC-EQX-CDs'!J$2:J$7) + SUMIF('Detalhes EC-EQX-CDs'!K$2:K$7,"Algar",'Detalhes EC-EQX-CDs'!Q$2:Q$7) + SUMIF('Detalhes EC-EQX-CDs'!Z$2:Z$7,"Algar",'Detalhes EC-EQX-CDs'!AF$2:AF$7) -> 2085.81 | I8: =IFERROR(H8/G8,0) -> 695.27
A9: Mundivox | B9: =COUNTIF('Detalhes Links Lojas'!D$2:D$216,"Mundivox") + COUNTIF('Detalhes Links Lojas'!L$2:L$216,"Mundivox") -> 24 | C9: =SUMIF('Detalhes Links Lojas'!D2:D216,"Mundivox",'Detalhes Links Lojas'!K2:K216) + SUMIF('Detalhes Links Lojas'!L2:L216,"Mundivox",'Detalhes Links Lojas'!S2:S216) -> 9291.91 | D9: =IFERROR(C9/B9,0) -> 387.16292 | F9: Megatelecom | G9: =COUNTIF('Detalhes EC-EQX-CDs'!D$2:D$7,"Megatelecom") + COUNTIF('Detalhes EC-EQX-CDs'!K$2:K$7,"Megatelecom") + COUNTIF('Detalhes EC-EQX-CDs'!Z$2:Z$7,"Megatelecom") -> 1 | H9: =SUMIF('Detalhes EC-EQX-CDs'!D$2:D$7,"Megatelecom",'Detalhes EC-EQX-CDs'!J$2:J$7) + SUMIF('Detalhes EC-EQX-CDs'!K$2:K$7,"Megatelecom",'Detalhes EC-EQX-CDs'!Q$2:Q$7) + SUMIF('Detalhes EC-EQX-CDs'!Z$2:Z$7,"Megatelecom",'Detalhes EC-EQX-CDs'!AF$2:AF$7) -> 997.79 | I9: =IFERROR(H9/G9,0) -> 997.79
A10: Oi | B10: =COUNTIF('Detalhes Links Lojas'!D$2:D$216,"Oi") + COUNTIF('Detalhes Links Lojas'!L$2:L$216,"Oi") -> 3 | C10: =SUMIF('Detalhes Links Lojas'!D$2:D$216,"Oi",'Detalhes Links Lojas'!K$2:K$216) + SUMIF('Detalhes Links Lojas'!L$2:L$216,"Oi",'Detalhes Links Lojas'!S$2:S$216) -> 2114.52 | D10: =IFERROR(C10/B10,0) -> 704.84 | F10: Total | G10: =SUM(G4:G9) -> 12 | H10: =SUM(H4:H9) -> 19940.09
A11: Algar | B11: =COUNTIF('Detalhes Links Lojas'!D$2:D$216,"Algar") + COUNTIF('Detalhes Links Lojas'!L$2:L$216,"Algar") -> 21 | C11: =SUMIF('Detalhes Links Lojas'!D$2:D$216,"Algar",'Detalhes Links Lojas'!K$2:K$216) + SUMIF('Detalhes Links Lojas'!L$2:L$216,"Algar",'Detalhes Links Lojas'!S$2:S$216) -> 9089.79 | D11: =IFERROR(C11/B11,0) -> 432.84714
A12: SEA Telecom | B12: =COUNTIF('Detalhes Links Lojas'!D$2:D$216,"SEA Telecom") + COUNTIF('Detalhes Links Lojas'!L$2:L$216,"SEA Telecom") -> 1 | C12: =SUMIF('Detalhes Links Lojas'!D$2:D$216,"SEA Telecom",'Detalhes Links Lojas'!K$2:K$216) + SUMIF('Detalhes Links Lojas'!L$2:L$216,"SEA Telecom",'Detalhes Links Lojas'!S$2:S$216) -> 189 | D12: =IFERROR(C12/B12,0) -> 189 | F12: Qtde de lojas | H12: =SUM('Por Loja'!D2:D216) -> 215
A13: SP18 | B13: =COUNTIF('Detalhes Links Lojas'!D$2:D$216,"SP18") + COUNTIF('Detalhes Links Lojas'!L$2:L$216,"SP18") -> 2 | C13: =SUMIF('Detalhes Links Lojas'!D$2:D$216,"SP18",'Detalhes Links Lojas'!K$2:K$216) + SUMIF('Detalhes Links Lojas'!L$2:L$216,"SP18",'Detalhes Links Lojas'!S$2:S$216) -> 1214.28 | D13: =IFERROR(C13/B13,0) -> 607.14
A14: Tesa | B14: =COUNTIF('Detalhes Links Lojas'!D$2:D$216,"Tesa") + COUNTIF('Detalhes Links Lojas'!L$2:L$216,"Tesa") -> 2 | C14: =SUMIF('Detalhes Links Lojas'!D$2:D$216,"Tesa",'Detalhes Links Lojas'!K$2:K$216) + SUMIF('Detalhes Links Lojas'!L$2:L$216,"Tesa",'Detalhes Links Lojas'!S$2:S$216) -> 1409.23 | D14: =IFERROR(C14/B14,0) -> 704.615
A15: Wipi | B15: =COUNTIF('Detalhes Links Lojas'!D$2:D$216,"Wipi") + COUNTIF('Detalhes Links Lojas'!L$2:L$216,"Wipi") -> 1 | C15: =SUMIF('Detalhes Links Lojas'!D$2:D$216,"Wipi",'Detalhes Links Lojas'!K$2:K$216) + SUMIF('Detalhes Links Lojas'!L$2:L$216,"Wipi",'Detalhes Links Lojas'!S$2:S$216) -> 710 | D15: =IFERROR(C15/B15,0) -> 710 | F15: Qtde de links | H15: =SUM(B21+G10) -> 441
A16: Megatelecom | B16: =COUNTIF('Detalhes Links Lojas'!D$2:D$216,"Megatelecom") + COUNTIF('Detalhes Links Lojas'!L$2:L$216,"Megatelecom") -> 0 | C16: =SUMIF('Detalhes Links Lojas'!D$2:D$216,"Megatelecom",'Detalhes Links Lojas'!K$2:K$216) + SUMIF('Detalhes Links Lojas'!L$2:L$216,"Megatelecom",'Detalhes Links Lojas'!S$2:S$216) -> 0 | D16: =IFERROR(C16/B16,0) -> 0
A17: WFT / AST | B17: =COUNTIF('Detalhes Links Lojas'!D$2:D$216,"WFT/AST") + COUNTIF('Detalhes Links Lojas'!L$2:L$216,"WFT/AST") -> 1 | C17: =SUMIF('Detalhes Links Lojas'!D$2:D$216,"WFT/AST",'Detalhes Links Lojas'!K$2:K$216) + SUMIF('Detalhes Links Lojas'!L$2:L$216,"WFT/AST",'Detalhes Links Lojas'!S$2:S$216) -> 200 | D17: =IFERROR(C17/B17,0) -> 200
A18: Vtal | B18: =COUNTIF('Detalhes Links Lojas'!D$2:D$216,"Vtal") + COUNTIF('Detalhes Links Lojas'!L$2:L$216,"Vtal") -> 21 | C18: =SUMIF('Detalhes Links Lojas'!D$2:D$216,"Vtal",'Detalhes Links Lojas'!K$2:K$216) + SUMIF('Detalhes Links Lojas'!L$2:L$216,"Vtal",'Detalhes Links Lojas'!S$2:S$216) -> 6694.63 | D18: =IFERROR(C18/B18,0) -> 318.7919 | F18: Custo total | H18: =SUM(C21+H10) -> 181880.27
A19: Irapido | B19: =COUNTIF('Detalhes Links Lojas'!D$2:D$216,"Irapido") + COUNTIF('Detalhes Links Lojas'!L$2:L$216,"Irapido") -> 3 | C19: =SUMIF('Detalhes Links Lojas'!D$2:D$216,"Irapido",'Detalhes Links Lojas'!K$2:K$216) + SUMIF('Detalhes Links Lojas'!L$2:L$216,"Irapido",'Detalhes Links Lojas'!S$2:S$216) -> 900 | D19: =IFERROR(C19/B19,0) -> 300
A20: ITS Brasil | B20: =COUNTIF('Detalhes Links Lojas'!D$2:D$216,"ITS Brasil") + COUNTIF('Detalhes Links Lojas'!L$2:L$216,"ITS Brasil") -> 1 | C20: =SUMIF('Detalhes Links Lojas'!D$2:D$216,"ITS Brasil",'Detalhes Links Lojas'!K$2:K$216) + SUMIF('Detalhes Links Lojas'!L$2:L$216,"ITS Brasil",'Detalhes Links Lojas'!S$2:S$216) -> 319.9 | D20: =IFERROR(C20/B20,0) -> 319.9
A21: Total | B21: =SUM(B4:B20) -> 429 | C21: =SUM(C4:C20) -> 161940.18

Sheet Dash-EC-EQX-CDs 
A1: SITE | B1: EC | C1: EQUINIX | D1: CD ITAQUA | E1: CD BLUMENAU | F1: CD GOIÂNIA | G1: CD NAVEGANTES
A2: CR | B2: EC | C2: EQX | D2: CD-820 | E2: CD-811 | F2: CD-807 | G2: CD-818
A3: OPERADORA 1 | B3: Claro | C3: Vivo | D3: =VLOOKUP($D$2,'Detalhes EC-EQX-CDs'!$A$2:$AF$7,4,FALSE) -> Vivo | E3: =VLOOKUP($E$2,'Detalhes EC-EQX-CDs'!$A$2:$AF$7,4,FALSE) -> Algar | F3: =VLOOKUP($F$2,'Detalhes EC-EQX-CDs'!$A$2:$AF$7,4,FALSE) -> Algar | G3: =VLOOKUP($G$2,'Detalhes EC-EQX-CDs'!$A$2:$AF$7,4,FALSE) -> Algar | I3: SITE | J3: QTDE LINKS | K3: VALOR
A4: TIPO | B4: Dedicado | C4: Dedicado | D4: =VLOOKUP($D$2,'Detalhes EC-EQX-CDs'!$A$2:$AF$7,9,FALSE) -> Dedicado | E4: =VLOOKUP($E$2,'Detalhes EC-EQX-CDs'!$A$2:$AF$7,9,FALSE) -> Dedicado | F4: =VLOOKUP($F$2,'Detalhes EC-EQX-CDs'!$A$2:$AF$7,9,FALSE) -> Dedicado | G4: =VLOOKUP($G$2,'Detalhes EC-EQX-CDs'!$A$2:$AF$7,9,FALSE) -> Dedicado | I4: EC | J4: 3 | K4: =SUM(B8+B15+B22) -> 9064.3
A5: VELOCIDADE | B5: 1Gbps | C5: 1 GB | D5: =VLOOKUP($D$2,'Detalhes EC-EQX-CDs'!$A$2:$AF$7,8,FALSE) -> 200Mb | E5: =VLOOKUP($E$2,'Detalhes EC-EQX-CDs'!$A$2:$AF$7,8,FALSE) -> 20Mb | F5: =VLOOKUP($F$2,'Detalhes EC-EQX-CDs'!$A$2:$AF$7,8,FALSE) -> 10Mb | G5: =VLOOKUP($G$2,'Detalhes EC-EQX-CDs'!$A$2:$AF$7,8,FALSE) -> 20Mb | I5: CD Itaqua | J5: 2 | K5: =SUM(D8+D15) -> 2340.03
A6: DATA DE ATIVAÇÃO | B6: 46112 | C6: 45568 | D6: =VLOOKUP($D$2,'Detalhes EC-EQX-CDs'!$A$2:$AF$7,5,FALSE) -> 45338 | E6: =VLOOKUP($E$2,'Detalhes EC-EQX-CDs'!$A$2:$AF$7,5,FALSE) -> 44596 | F6: =VLOOKUP($F$2,'Detalhes EC-EQX-CDs'!$A$2:$AF$7,5,FALSE) -> 44617 | G6: =VLOOKUP($G$2,'Detalhes EC-EQX-CDs'!$A$2:$AF$7,5,FALSE) -> 44589 | I6: CD Blumenau | J6: 2 | K6: =SUM(E8+E15) -> 1986.5
A7: VIGÊNCIA | B7: 47208 | C7: 46663 | D7: =VLOOKUP($D$2,'Detalhes EC-EQX-CDs'!$A$2:$AF$7,6,FALSE) -> 46434 | E7: =VLOOKUP($E$2,'Detalhes EC-EQX-CDs'!$A$2:$AF$7,6,FALSE) -> Vencido | F7: =VLOOKUP($F$2,'Detalhes EC-EQX-CDs'!$A$2:$AF$7,6,FALSE) -> Vencido | G7: =VLOOKUP($G$2,'Detalhes EC-EQX-CDs'!$A$2:$AF$7,6,FALSE) -> Vencido | I7: CD Goiânia | J7: 2 | K7: =SUM(F8+F15) -> 850.62
A8: VALOR | B8: 2914.3 | C8: 4110.16 | D8: =VLOOKUP($D$2,'Detalhes EC-EQX-CDs'!$A$2:$AF$7,10,FALSE) -> 1910.03 | E8: =VLOOKUP($E$2,'Detalhes EC-EQX-CDs'!$A$2:$AF$7,10,FALSE) -> 1024.5 | F8: =VLOOKUP($F$2,'Detalhes EC-EQX-CDs'!$A$2:$AF$7,10,FALSE) -> 470.62 | G8: =VLOOKUP($G$2,'Detalhes EC-EQX-CDs'!$A$2:$AF$7,10,FALSE) -> 590.69 | I8: CD Navegantes | J8: 2 | K8: =SUM(G8+G15) -> 1588.48
A9: DESIGNAÇÃO | B9: SPO/IP/40295 | C9: 110005641701194 | D9: =VLOOKUP($D$2,'Detalhes EC-EQX-CDs'!$A$2:$AF$7,7,FALSE) -> 113004643101796 | E9: =VLOOKUP($E$2,'Detalhes EC-EQX-CDs'!$A$2:$AF$7,7,FALSE) -> 8756818/8756819 | F9: =VLOOKUP($F$2,'Detalhes EC-EQX-CDs'!$A$2:$AF$7,7,FALSE) -> 8754445/8754447 | G9: =VLOOKUP($G$2,'Detalhes EC-EQX-CDs'!$A$2:$AF$7,7,FALSE) -> 8754444/8754446 | I9: Equinix | J9: 1 | K9: =SUM(C8+C15+C22+C29) -> 4110.16
A10: OPERADORA 2 | B10: Mundivox | D10: =VLOOKUP($D$2,'Detalhes EC-EQX-CDs'!$A$2:$AF$7,11,FALSE) -> Fibrion | E10: Claro | F10: Vivo | G10: MegaTelecom | I10: Custo Total | J10: =SUM(J4:J9) -> 12 | K10: =SUM(K4:K9) -> 19940.09
A11: TIPO | B11: Dedicado | D11: =VLOOKUP($D$2,'Detalhes EC-EQX-CDs'!$A$2:$AF$7,16,FALSE) -> Dedicado | E11: =VLOOKUP($E$2,'Detalhes EC-EQX-CDs'!$A$2:$AF$7,16,FALSE) -> Dedicado | F11: =VLOOKUP($F$2,'Detalhes EC-EQX-CDs'!$A$2:$AF$7,16,FALSE) -> Dedicado | G11: =VLOOKUP($G$2,'Detalhes EC-EQX-CDs'!$A$2:$AF$7,16,FALSE) -> Dedicado
A12: VELOCIDADE | B12: 1Gbps | D12: =VLOOKUP($D$2,'Detalhes EC-EQX-CDs'!$A$2:$AF$7,15,FALSE) -> 100Mb | E12: =VLOOKUP($E$2,'Detalhes EC-EQX-CDs'!$A$2:$AF$7,15,FALSE) -> 50Mb | F12: =VLOOKUP($F$2,'Detalhes EC-EQX-CDs'!$A$2:$AF$7,15,FALSE) -> 20Mb | G12: =VLOOKUP($G$2,'Detalhes EC-EQX-CDs'!$A$2:$AF$7,15,FALSE) -> 20Mb
A13: DATA DE ATIVAÇÃO | B13: 46010 | D13: =VLOOKUP($D$2,'Detalhes EC-EQX-CDs'!$A$2:$AF$7,12,FALSE) -> 45609 | E13: =VLOOKUP($E$2,'Detalhes EC-EQX-CDs'!$A$2:$AF$7,12,FALSE) -> 46218 | F13: =VLOOKUP($F$2,'Detalhes EC-EQX-CDs'!$A$2:$AF$7,12,FALSE) -> 46176 | G13: =VLOOKUP($G$2,'Detalhes EC-EQX-CDs'!$A$2:$AF$7,12,FALSE) -> 44735 | I13: OPERADORA | J13: QTDE LINKS | K13: CUSTO
A14: VIGÊNCIA | B14: 47106 | D14: =VLOOKUP($D$2,'Detalhes EC-EQX-CDs'!$A$2:$AF$7,13,FALSE) -> 46704 | E14: =VLOOKUP($E$2,'Detalhes EC-EQX-CDs'!$A$2:$AF$7,13,FALSE) -> 47314 | F14: =VLOOKUP($F$2,'Detalhes EC-EQX-CDs'!$A$2:$AF$7,13,FALSE) -> 47272 | G14: =VLOOKUP($G$2,'Detalhes EC-EQX-CDs'!$A$2:$AF$7,13,FALSE) -> Vencido | I14: Vivo | J14: 4 | K14: =SUM(B22+C8+D8+F15) -> 9800.19
A15: VALOR | B15: 2750 | D15: =VLOOKUP($D$2,'Detalhes EC-EQX-CDs'!$A$2:$AF$7,17,FALSE) -> 430 | E15: =VLOOKUP($E$2,'Detalhes EC-EQX-CDs'!$A$2:$AF$7,17,FALSE) -> 962 | F15: =VLOOKUP($F$2,'Detalhes EC-EQX-CDs'!$A$2:$AF$7,17,FALSE) -> 380 | G15: =VLOOKUP($G$2,'Detalhes EC-EQX-CDs'!$A$2:$AF$7,17,FALSE) -> 997.79 | I15: Claro | J15: 2 | K15: =SUM(B8+E15) -> 3876.3
A16: DESIGNAÇÃO | B16: 11020625 | D16: =VLOOKUP($D$2,'Detalhes EC-EQX-CDs'!$A$2:$AF$7,14,FALSE) -> ZZ45726039001 | E16: =VLOOKUP($E$2,'Detalhes EC-EQX-CDs'!$A$2:$AF$7,14,FALSE) -> BNU/IP/01514 | F16: =VLOOKUP($F$2,'Detalhes EC-EQX-CDs'!$A$2:$AF$7,14,FALSE) -> 621980221280394 | G16: =VLOOKUP($G$2,'Detalhes EC-EQX-CDs'!$A$2:$AF$7,14,FALSE) -> TIT000872 | I16: Algar | J16: 3 | K16: =SUM(E8+F8+G8) -> 2085.81
A17: OPERADORA 3 | B17: Vivo | I17: WCS | J17: 1 | K17: =SUM(D15) -> 430
A18: TIPO | B18: Dedicado | I18: Mega Telecom | J18: 1 | K18: =SUM(G15) -> 997.79
A19: VELOCIDADE | B19: 1 GB | I19: Mundivox | J19: 1 | K19: =SUM(B15) -> 2750
A20: DATA DE ATIVAÇÃO | B20: 46024 | I20: Total | J20: =SUM(J14:J19) -> 12 | K20: =SUM(K14:K19) -> 19940.09
A21: VIGÊNCIA | B21: 47120
A22: VALOR | B22: 3400
A23: DESIGNAÇÃO | B23: 110003825281299

Sheet Espelho EC-CDs-2025
A1: SITE | B1: EC | C1: TIVIT | D1: EQUINIX | E1: CD ITAQUA | F1: CD BLUMENAU | G1: CD GOIÂNIA | H1: CD NAVEGANTES | I1: SITEF
A2: CR | B2: 41100 | C2: TIVIT | E2: CD-820 | F2: CD-811 | G2: CD-807 | H2: CD-818 | I2: SITEF 2 | J2: SITEF 1
A3: OPERADORA 1 | B3: Embratel | C3: Embratel | E3: Vivo | F3: Algar | G3: Algar | H3: Algar | I3: Vivo | J3: Vivo | L3: SITE | M3: QTDE LINKS | N3: VALOR
A4: TIPO | B4: Dedicado | C4: Dedicado | E4: Dedicado | F4: Dedicado | G4: Dedicado | H4: Dedicado | I4: MPLS -P2 EQN-ALA | J4: MPLS -P1 EQN-MIG | L4: EC | M4: 4 | N4: =SUM(B8+B15+B22+B29) -> 12033.18
A5: VELOCIDADE | B5: 500Mb | C5: 1Gb | E5: 200Mb | F5: 20Mb | G5: 10Mb | H5: 20Mb | I5: 2Mb | J5: 2Mb | L5: TIVIT | M5: 4 | N5: =SUM(C8+C15+C22+C36) -> 13272.39
A6: DATA DE ATIVAÇÃO | B6: 44903 | C6: 44901 | E6: 45338 | F6: 44596 | G6: 44617 | H6: 44589 | I6: 43738 | J6: 43738 | L6: CD Itaqua | M6: 3 | N6: =SUM(E8+E15+E22) -> 3374.59
A7: VIGÊNCIA | B7: 45999 | C7: Cancelado | E7: 46434 | F7: Vencido | G7: Vencido | H7: Vencido | I7: Cancelado | J7: Cancelado | L7: CD Blumenau | M7: 2 | N7: =SUM(F8+F15) -> 1464.36
A8: VALOR | B8: 3198.68 | C8: 5657.1 | E8: 1910.03 | F8: 952.94 | G8: 440.78 | H8: 562.27 | I8: 832.3 | J8: 832.3 | L8: CD Goiânia | M8: 2 | N8: =SUM(G8+G15) -> 1025.42
A9: DESIGNAÇÃO | B9: SPO/IP/40295 | C9: SPO/IP/70714 | E9: 113004643101796 | F9: 8756818/8756819 | G9: 8754445/8754447 | H9: 8754444/8754446 | I9: 110714191224793 | J9: 110003106383097 | L9: CD Navegantes | M9: 2 | N9: =SUM(H8+H15) -> 1560.06
A10: OPERADORA 2 | B10: Vivo | C10: Vivo | E10: WCS | F10: Embratel | G10: Vivo | H10: MegaTelecom | I10: Embratel | J10: Embratel | L10: SITEF | M10: 6 | N10: =SUM(I8+J8+I15+J15+C29+C43) -> 13984.59
A11: TIPO | B11: Dedicado | C11: Dedicado | E11: Dedicado | F11: Dedicado | G11: Dedicado | H11: Dedicado | I11: MPLS | J11: MPLS | L11: Equinix | M11: 1 | N11: =SUM(D8+D15+D22+D29) -> 3025.46
A12: VELOCIDADE | B12: 1 GB | C12: 1 GB | E12: 100 MB | F12: 20 MB | G12: 10 MB | H12: 20 MB | I12: 2Mb | J12: 2Mb | L12: Custo Total | M12: =SUM(M4:M10) -> 23 | N12: =SUM(N4:N11) -> 49740.05
A13: DATA DE ATIVAÇÃO | B13: 45595 | C13: 45132 | E13: 45609 | F13: 44714 | G13: 44470 | H13: 44735 | I13: 43346 | J13: 43361
A14: VIGÊNCIA | B14: 46690 | C14: 46228 | E14: 46704 | F14: Vencido | G14: Vencido | H14: Vencido | I14: Cancelado | J14: Cancelado
A15: VALOR | B15: 3613.93 | C15: 4110.16 | E15: 430 | F15: 511.42 | G15: 584.64 | H15: 997.79 | I15: 1343.81 | J15: 1909.68 | L15: OPERADORA | M15: QTDE LINKS | N15: CUSTO
A16: DESIGNAÇÃO | B16: 110003392209490 | C16: 110005641701194 | E16: CD 820 - Itaquaquecetuba - SP | F16: BNU/IP/01514 | G16: 621980152126996 | H16: TIT000872 | I16: BRE/IP/25280 | J16: SPO/IP/55325 | L16: Vivo | M16: 8 | N16: =SUM(E8+I8+J8+B15+G15+C43+C15+D29) -> 18982.26
A17: OPERADORA 3 | B17: Algar | C17: Algar | E17: Algar | L17: Embratel | M17: 6 | N17: =SUM(C29+J15+I15+F15+C8+B8) -> 17613.75
A18: TIPO | B18: L2L (EC-Tivit) | C18: L2L (Tivit-EC) | E18: L2L (CD-Tivit) | L18: Algar | M18: 7 | N18: =SUM(C36+E22+C22+B22+F8+G8+H8) -> 8966.25
A19: VELOCIDADE | B19: 1 GB | C19: 1 GB | E19: 50Mb | L19: WCS | M19: 1 | N19: =SUM(E15) -> 430
A20: DATA DE ATIVAÇÃO | B20: 44750 | C20: 44750 | E20: 44651 | H20: Cancelamentos | L20: Mega Telecom | M20: 1 | N20: =SUM(H15) -> 997.79
A21: VIGÊNCIA | B21: Cancelado | C21: Cancelado | E21: Cancelado | L21: Mundivox | M21: 1 | N21: =SUM(B29) -> 2750
A22: VALOR | B22: 2470.57 | C22: 2470.57 | E22: 1034.56 | H22: Operadora | I22: Tipo | J22: Data solicitação | L22: Total | M22: =SUM(M16:M20) -> 23 | N22: =SUM(N16:N21) -> 49740.05
A23: DESIGNAÇÃO | B23: 8880105 | C23: 8880104 | E23: 8788650 | H23: Embratel | I23: Dedicado - Tivit | J23: 46037 | K23: sem cob em mar/26
A24: OPERADORA 4 | B24: Mundivox | C24: Embratel | D24: Vivo | H24: Vivo | I24: Dedicado - EC antigo | J24: 46035 | K24: sem cob em mar/26
A25: TIPO | B25: Dedicado | C25: MPLS - (Sitef) | D25: L2L (EC-Equinix) | H25: Vivo | I25: L2L (EC-Equinix) | J25: 46015 | K25: sem cobr em fev/26
A26: VELOCIDADE | B26: 1Gbps | C26: 20MB | D26: 1 Gb | H26: Algar | I26: Lan2lan (CD-Tivit) | J26: 45985 | K26: sem cob em mar/26
A27: DATA DE ATIVAÇÃO | B27: 46010 | C27: 43383 | D27: 45782 | H27: Algar | I27: Lan2lan (EC-Tivit) | J27: 45975 | K27: sem cob em mar/26
A28: VIGÊNCIA | B28: 47106 | C28: Cancelado | D28: 46878 | H28: Vivo | I28: MPLS -P2 EQN-ALA | J28: 45951 | K28: sem cob jan/26
A29: VALOR | B29: 2750 | C29: 4993.06 | D29: 3025.46 | H29: Vivo | I29: MPLS -P2 EQN-MIG | J29: 45951 | K29: sem cob jan/26
A30: DESIGNAÇÃO | B30: 11020625 | C30: SPO/IP/55340 | D30: 110003392058297 | H30: Vivo | I30: MPLS - (sitef) | J30: 45951 | K30: sem cobrança dez/25
A31: OPERADORA 5 | C31: Algar | H31: Embratel | I31: MPLS -P2 EQN-ALA | J31: 45951 | K31: sem cobr em fev/26
A32: TIPO | C32: L2L(Tivit-CD) | H32: Embratel | I32: MPLS -P2 EQN-MIG | J32: 45951 | K32: sem cobr em fev/26
A33: VELOCIDADE | C33: 50Mb | H33: Embratel | I33: MPLS - (sitef) | J33: 45951 | K33: sem cobr em fev/26
A34: DATA DE ATIVAÇÃO | C34: 44651
A35: VIGÊNCIA | C35: Cancelado
A36: VALOR | C36: 1034.56
A37: DESIGNAÇÃO | C37: 8788652
A38: OPERADORA 6 | C38: Vivo
A39: TIPO | C39: MPLS - (Sitef)
A40: VELOCIDADE | C40: 4Mb
...

Sheet PPOE Lojas
A1: PPOE LOJAS
A2: Loja | B2: Operadora | C2: Ip | D2: Mascara | E2: Gateway | F2: Data da alteração | G2: Velocidade | H2: Obs | I2: User | J2: Passoword
A3: 651 | B3: SPIN18 | C3: 45172162196 | D3: 255255255255 | E3: 10.65.14.1 | F3: 45848 | G3: 10Mb ded | H3: link já estava ativo/ alterou para PPOE o acesso | I3: spin18_marisa | J3: HBQPGEDL
A4: 868 | B4: VERO | C4: 100.64.98.138 | D4: 255255255255 | E4: 186225116129 | F4: 45838 | G4: 300Mb ADSL | H4: link já estava ativo/ alterou para PPOE o acesso | I4: A077474100037@sp.spo | J4: 8qpqmypdipmv
A5: 888 | B5: VERO | C5: 100.64.105.112 | D5: 255255255255 | E5: 186225116129 | F5: 45838 | G5: 300Mb ADSL | H5: link já estava ativo/ alterou para PPOE o acesso | I5: A077474100031@rs.pae | J5: h0m8pphrroel

Sheet Por Loja
A1: Loja | B1: Operadora 1 | C1: Operadora 2 | D1: Qtde
A2: 22 | B2: =VLOOKUP(A2,'Detalhes Links Lojas'!A2:D216,4) -> Claro | C2: =VLOOKUP(A2,'Detalhes Links Lojas'!A2:L216,12) -> Vero | D2: 1
A3: 43 | B3: =VLOOKUP(A3,'Detalhes Links Lojas'!A3:D217,4) -> Mundivox | C3: =VLOOKUP(A3,'Detalhes Links Lojas'!A3:L217,12) -> Vero | D3: 1
A4: 80 | B4: =VLOOKUP(A4,'Detalhes Links Lojas'!A4:D218,4) -> Claro | C4: =VLOOKUP(A4,'Detalhes Links Lojas'!A4:L218,12) -> Vivo | D4: 1
A5: 87 | B5: =VLOOKUP(A5,'Detalhes Links Lojas'!A5:D219,4) -> Claro | C5: =VLOOKUP(A5,'Detalhes Links Lojas'!A5:L219,12) -> Vivo | D5: 1
A6: 120 | B6: =VLOOKUP(A6,'Detalhes Links Lojas'!A6:D220,4) -> Vtal | C6: =VLOOKUP(A6,'Detalhes Links Lojas'!A6:L220,12) -> Fibrion | D6: 1
A7: 125 | B7: =VLOOKUP(A7,'Detalhes Links Lojas'!A7:D221,4) -> Claro | C7: =VLOOKUP(A7,'Detalhes Links Lojas'!A7:L221,12) -> Vivo | D7: 1
A8: 130 | B8: =VLOOKUP(A8,'Detalhes Links Lojas'!A8:D222,4) -> Claro | C8: =VLOOKUP(A8,'Detalhes Links Lojas'!A8:L222,12) -> Vivo | D8: 1
A9: 133 | B9: =VLOOKUP(A9,'Detalhes Links Lojas'!A9:D223,4) -> Claro | C9: =VLOOKUP(A9,'Detalhes Links Lojas'!A9:L223,12) -> SP18 | D9: 1
A10: 135 | B10: =VLOOKUP(A10,'Detalhes Links Lojas'!A10:D223,4) -> Algar | C10: =VLOOKUP(A10,'Detalhes Links Lojas'!A10:L223,12) -> Claro | D10: 1
A11: 136 | B11: =VLOOKUP(A11,'Detalhes Links Lojas'!A11:D223,4) -> Mundivox | C11: =VLOOKUP(A11,'Detalhes Links Lojas'!A11:L223,12) -> Vero | D11: 1
A12: 140 | B12: =VLOOKUP(A12,'Detalhes Links Lojas'!A12:D224,4) -> Vtal | C12: =VLOOKUP(A12,'Detalhes Links Lojas'!A12:L224,12) -> Claro | D12: 1
A13: 142 | B13: =VLOOKUP(A13,'Detalhes Links Lojas'!A13:D225,4) -> Mundivox | C13: =VLOOKUP(A13,'Detalhes Links Lojas'!A13:L225,12) -> Vero | D13: 1
A14: 150 | B14: =VLOOKUP(A14,'Detalhes Links Lojas'!A14:D226,4) -> Claro | C14: =VLOOKUP(A14,'Detalhes Links Lojas'!A14:L226,12) -> Fibrion | D14: 1
A15: 160 | B15: =VLOOKUP(A15,'Detalhes Links Lojas'!A15:D227,4) -> Claro | C15: =VLOOKUP(A15,'Detalhes Links Lojas'!A15:L227,12) -> Vivo | D15: 1
A16: 165 | B16: =VLOOKUP(A16,'Detalhes Links Lojas'!A16:D228,4) -> Mundivox | C16: =VLOOKUP(A16,'Detalhes Links Lojas'!A16:L228,12) -> Vero | D16: 1
A17: 176 | B17: =VLOOKUP(A17,'Detalhes Links Lojas'!A17:D229,4) -> Mundivox | C17: =VLOOKUP(A17,'Detalhes Links Lojas'!A17:L229,12) -> Vero | D17: 1
A18: 178 | B18: =VLOOKUP(A18,'Detalhes Links Lojas'!A18:D230,4) -> Claro | C18: =VLOOKUP(A18,'Detalhes Links Lojas'!A18:L230,12) -> Vivo | D18: 1
A19: 180 | B19: =VLOOKUP(A19,'Detalhes Links Lojas'!A19:D231,4) -> Fibrion | C19: =VLOOKUP(A19,'Detalhes Links Lojas'!A19:L231,12) -> Claro | D19: 1
A20: 196 | B20: =VLOOKUP(A20,'Detalhes Links Lojas'!A20:D232,4) -> Claro | C20: =VLOOKUP(A20,'Detalhes Links Lojas'!A20:L232,12) -> Irapido | D20: 1
A21: 508 | B21: =VLOOKUP(A21,'Detalhes Links Lojas'!A21:D233,4) -> Claro | C21: =VLOOKUP(A21,'Detalhes Links Lojas'!A21:L233,12) -> Vivo | D21: 1
A22: 510 | B22: =VLOOKUP(A22,'Detalhes Links Lojas'!A22:D234,4) -> Claro | C22: =VLOOKUP(A22,'Detalhes Links Lojas'!A22:L234,12) -> Tesa | D22: 1
A23: 514 | B23: =VLOOKUP(A23,'Detalhes Links Lojas'!A23:D237,4) -> Claro | C23: =VLOOKUP(A23,'Detalhes Links Lojas'!A23:L237,12) -> Vivo | D23: 1
A24: 515 | B24: =VLOOKUP(A24,'Detalhes Links Lojas'!A24:D238,4) -> Mundivox | C24: =VLOOKUP(A24,'Detalhes Links Lojas'!A24:L238,12) -> Vero | D24: 1
A25: 517 | B25: =VLOOKUP(A25,'Detalhes Links Lojas'!A25:D239,4) -> Claro | C25: =VLOOKUP(A25,'Detalhes Links Lojas'!A25:L239,12) -> Vtal | D25: 1
A26: 518 | B26: =VLOOKUP(A26,'Detalhes Links Lojas'!A26:D240,4) -> Claro | C26: =VLOOKUP(A26,'Detalhes Links Lojas'!A26:L240,12) -> Vero | D26: 1
A27: 519 | B27: =VLOOKUP(A27,'Detalhes Links Lojas'!A27:D241,4) -> Vtal | C27: =VLOOKUP(A27,'Detalhes Links Lojas'!A27:L241,12) -> Claro | D27: 1
A28: 520 | B28: =VLOOKUP(A28,'Detalhes Links Lojas'!A28:D242,4) -> Claro | C28: =VLOOKUP(A28,'Detalhes Links Lojas'!A28:L242,12) -> Vero | D28: 1
A29: 525 | B29: =VLOOKUP(A29,'Detalhes Links Lojas'!A29:D243,4) -> Claro | C29: =VLOOKUP(A29,'Detalhes Links Lojas'!A29:L243,12) -> Vivo | D29: 1
A30: 526 | B30: =VLOOKUP(A30,'Detalhes Links Lojas'!A30:D244,4) -> Algar | C30: =VLOOKUP(A30,'Detalhes Links Lojas'!A30:L244,12) -> Vero | D30: 1
A31: 527 | B31: =VLOOKUP(A31,'Detalhes Links Lojas'!A31:D245,4) -> Claro | C31: =VLOOKUP(A31,'Detalhes Links Lojas'!A31:L245,12) -> Irapido | D31: 1
A32: 529 | B32: =VLOOKUP(A32,'Detalhes Links Lojas'!A32:D246,4) -> Claro | C32: =VLOOKUP(A32,'Detalhes Links Lojas'!A32:L246,12) -> Vero | D32: 1
A33: 531 | B33: =VLOOKUP(A33,'Detalhes Links Lojas'!A33:D247,4) -> Mundivox | C33: =VLOOKUP(A33,'Detalhes Links Lojas'!A33:L247,12) -> Vivo | D33: 1
A34: 534 | B34: =VLOOKUP(A34,'Detalhes Links Lojas'!A34:D248,4) -> Fibrion | C34: =VLOOKUP(A34,'Detalhes Links Lojas'!A34:L248,12) -> Claro | D34: 1
... A36: 536 | B36: =VLOOKUP(A36,'Detalhes Links Lojas'!A36:D250,4) -> Algar | C36: =VLOOKUP(A36,'Detalhes Links Lojas'!A36:L250,12) -> Claro | D36: 1
A37: 544 | B37: =VLOOKUP(A37,'Detalhes Links Lojas'!A37:D252,4) -> Mundivox | C37: =VLOOKUP(A37,'Detalhes Links Lojas'!A37:L252,12) -> Vero | D37: 1
A38: 546 | B38: =VLOOKUP(A38,'Detalhes Links Lojas'!A38:D253,4) -> Claro | C38: =VLOOKUP(A38,'Detalhes Links Lojas'!A38:L253,12) -> Vero | D38: 1
A39: 547 | B39: =VLOOKUP(A39,'Detalhes Links Lojas'!A39:D254,4) -> Fibrion | C39: =VLOOKUP(A39,'Detalhes Links Lojas'!A39:L254,12) -> Vero | D39: 1
A40: 548 | B40: =VLOOKUP(A40,'Detalhes Links Lojas'!A40:D255,4) -> Claro | C40: =VLOOKUP(A40,'Detalhes Links Lojas'!A40:L255,12) -> Vivo | D40: 1
A41: 549 | B41: =VLOOKUP(A41,'Detalhes Links Lojas'!A41:D256,4) -> Claro | C41: =VLOOKUP(A41,'Detalhes Links Lojas'!A41:L256,12) -> Vero | D41: 1
...

Sheet Ips Link Novos
A1: Ip Links Contratados
A2: Loja | B2: Operadora | C2: Ip | D2: Mascara | E2: Gateway | F2: Data Ativação | G2: Velocidade | H2: Obs
A3: 682 | B3: Claro | C3: 200.246.15.46 | D3: 255255255252 | E3: 200.246.15.45 | F3: 45838 | G3: 20Mb dedicado
A4: 601 | B4: Claro | C4: DHCP | D4: --- | E4: 192.168.0.1 | F4: 45895 | G4: 600Mb ADSL
A5: 600 | B5: Mundivox | C5: 187.103.33.18 | D5: 255255255252 | E5: 187.103.33.17 | F5: 45896 | G5: 100Mb semidedicado | H5: Faixa de IPs: 187.103.33.18 a 187.103.33.18 | I5: Gateway: 187.103.33.17 | J5: Máscara de Sub-rede: 255.255.255.252 | K5: DNS Primário: 200.196.48.20 | L5: DNS Secundário: 179.191.120.5
A6: 140 | B6: Claro | C6: 200.179.90.106 | D6: 255255255252 | E6: 200.179.90.105 | F6: 45896 | G6: 20Mb dedicado
A7: 662 | B7: Mundivox | C7: DHCP | D7: --- | E7: --- | F7: 45896 | G7: 100Mb semidedicado
A8: 565 | B8: Mundivox | C8: DHCP | D8: --- | E8: --- | F8: 45898 | G8: 100Mb semidedicado
A9: 885 | B9: Mundivox | C9: DHCP | D9: --- | E9: --- | F9: 45898 | G9: 100Mb semidedicado | H9: Faixa de IPs: 177.92.98.246 a 177.92.98.246 | I9: Gateway: 177.92.98.245 | J9: Máscara de Sub-rede: 255.255.255.252 | K9: DNS Primário: 200.196.48.20 | L9: DNS Secundário: 179.191.120.5
A10: 8 5 8 | B10: Mundivox | C10: DHCP | D10: --- | E10: --- | F10: 45901 | G10: 100Mb semidedicado
A11: 601 | B11: Mundivox | C11: DHCP | D11: --- | E11: --- | F11: 45902 | G11: 100Mb semidedicado
A12: 744 | B12: Vivo | C12: DHCP | D12: --- | E12: --- | F12: 45902 | G12: 600Mb ADSL
A13: 43 | B13: Mundivox | C13: DHCP | D13: --- | E13: --- | F13: 45904 | G13: 100Mb semidedicado
A14: 550 | B14: Mundivox | C14: DHCP | D14: --- | E14: --- | F14: 45904 | G14: 100Mb semidedicado
A15: 889 | B15: Mundivox | C15: DHCP | D15: --- | E15: --- | F15: 45904 | G15: 100Mb semidedicado
A16: 586 | B16: Mundivox | C16: DHCP | D16: --- | E16: --- | F16: 45910 | G16: 100Mb semidedicado
A17: 640 | B17: Mundivox | C17: DHCP | D17: --- | E17: --- | F17: 45915 | G17: 100Mb semidedicado
A18: 675 | B18: Algar | C18: 187.32.33.21 | D18: 255255255252 | E18: 187.32.33.22 | F18: 45916 | G18: 20Mb dedicado
A19: 125 | B19: Vivo | C19: DHCP | D19: --- | E19: --- | F19: 45917 | G19: 600Mb ADSL
A20: 877 | B20: Vivo | C20: DHCP | D20: --- | E20: --- | F20: 45919 | G20: 600Mb ADSL
A21: 568 | B21: Algar | C21: 189.38.108.41 | D21: 255255255252 | E21: 189.38.108.42 | F21: 45919 | G21: 20Mb dedicado
A22: 589 | B22: Vivo | C22: DHCP | D22: --- | E22: --- | F22: 45922 | G22: 600Mb ADSL
A23: 770 | B23: Vivo | C23: DHCP | D23: --- | E23: --- | F23: 45922 | G23: 600Mb ADSL
A24: 719 | B24: Vivo | C24: DHCP | D24: --- | E24: --- | F24: 45922 | G24: 600Mb ADSL
A25: 774 | B25: Mundivox | C25: DHCP | D25: --- | E25: --- | F25: 45925 | G25: 100Mb semidedicado
A26: 563 | B26: Algar | C26: 189.112.203.69 | D26: 255255255252 | E26: 189.112.203.70 | F26: 45925 | G26: 20Mb dedicado
A27: 751 | B27: Vivo | C27: DHCP | D27: --- | E27: --- | F27: 45926 | G27: 600Mb ADSL
A28: 929 | B28: Mundivox | C28: DHCP | D28: --- | E28: --- | F28: 45926 | G28: 100Mb semidedicado
A29: 921 | B29: Algar | C29: 187.72.10.73 | D29: 255255255252 | E29: 187.72.10.74 | F29: 45936 | G29: 20Mb dedicado
A30: 867 | B30: Algar | C30: 200233218229 | D30: 255255255252 | E30: 200233218230 | F30: 45937 | G30: 20Mb dedicado
A31: 590 | B31: Mundivox | C31: DHCP | D31: --- | E31: --- | F31: 45938 | G31: 100Mb semidedicado
A32: 848 | B32: Claro | C32: DHCP | D32: --- | E32: --- | F32: 45939 | G32: 300Mb ADSL
A33: 893 | B33: Claro | C33: DHCP | D33: --- | E33: --- | F33: 45939 | G33: 300Mb ADSL
A34: 709 | B34: Claro | C34: 189.2.77.222 | D34: 255255255252 | E34: 189.2.77.221 | F34: 45943 | G34: 20Mb dedicado
A35: 645 | B35: Claro | C35: 200212229250 | D35: 255255255252 | E35: 200212229249 | F35: 45944 | G35: 20Mb dedicado
A36: 576 | B36: Mundivox | C36: DHCP | D36: --- | E36: --- | F36: 45944 | G36: 100Mb semidedicado
A37: 580 | B37: Vivo | C37: DHCP | D37: --- | E37: --- | F37: 45944 | G37: 600Mb ADSL
A38: 943 | B38: Claro | C38: 200213117214 | D38: 255255255252 | E38: 200213117213 | F38: 45945 | G38: 20Mb dedicado
A39: 565 | B39: Claro | C39: DHCP | D39: --- | E39: --- | F39: 45945 | G39: 300Mb ADSL
A40: 598 | B40: Vivo | C40: DHCP | D40: --- | E40: --- | F40: 45946 | G40: 600Mb ADSL
...

Sheet Detalhes EC-EQX-CDs
